Workbook

Sheet Income Statement
A1: Apple Inc. — Consolidated Statements of Operations
A2: (In millions USD, except per-share amounts) — Fiscal Years Ended Sept
A4: Income Statement Item | B4: FY2023 | C4: FY2024 | D4: FY2025 | E4: FY24 vs FY23 % | F4: FY25 vs FY24 % | G4: FY23 % Sales | H4: FY24 % Sales | I4: FY25 % Sales
A5: Net Sales:
A6: Products | B6: 298085 | C6: 294866 | D6: 307003 | E6: =(C6-B6)/B6 -> -0.010798933 | F6: =(D6-C6)/C6 -> 0.04116107 | G6: =B6/$B$8 -> 0.7777111 | H6: =C6/$C$8 -> 0.75406549 | I6: =D6/$D$8 -> 0.73770248
A7: Services | B7: 85200 | C7: 96169 | D7: 109158 | E7: =(C7-B7)/B7 -> 0.12874413 | F7: =(D7-C7)/C7 -> 0.13506431 | G7: =B7/$B$8 -> 0.2222889 | H7: =C7/$C$8 -> 0.24593451 | I7: =D7/$D$8 -> 0.26229752
A8: Total Net Sales | B8: =SUM(B6:B7) -> 383285 | C8: =SUM(C6:C7) -> 391035 | D8: =SUM(D6:D7) -> 416161 | E8: =(C8-B8)/B8 -> 0.020219941 | F8: =(D8-C8)/C8 -> 0.064255118 | G8: =B8/$B$8 -> 1 | H8: =C8/$C$8 -> 1 | I8: =D8/$D$8 -> 1
A9: Cost of Sales:
A10: Products | B10: 189282 | C10: 185233 | D10: 194116 | E10: =(C10-B10)/B10 -> -0.021391363 | F10: =(D10-C10)/C10 -> 0.047955818 | G10: =B10/$B$8 -> 0.4938414 | H10: =C10/$C$8 -> 0.47369929 | I10: =D10/$D$8 -> 0.46644448
A11: Services | B11: 24855 | C11: 25119 | D11: 26844 | E11: =(C11-B11)/B11 -> 0.010621605 | F11: =(D11-C11)/C11 -> 0.068673116 | G11: =B11/$B$8 -> 0.064847307 | H11: =C11/$C$8 -> 0.064237217 | I11: =D11/$D$8 -> 0.064503882
A12: Total Cost of Sales | B12: =SUM(B10:B11) -> 214137 | C12: =SUM(C10:C11) -> 210352 | D12: =SUM(D10:D11) -> 220960 | E12: =(C12-B12)/B12 -> -0.0176756 | F12: =(D12-C12)/C12 -> 0.050429756 | G12: =B12/$B$8 -> 0.5586887 | H12: =C12/$C$8 -> 0.5379365 | I12: =D12/$D$8 -> 0.53094836
A13: Gross Margin | B13: =B8-B12 -> 169148 | C13: =C8-C12 -> 180683 | D13: =D8-D12 -> 195201 | E13: =(C13-B13)/B13 -> 0.068194717 | F13: =(D13-C13)/C13 -> 0.080350669 | G13: =B13/$B$8 -> 0.4413113 | H13: =C13/$C$8 -> 0.4620635 | I13: =D13/$D$8 -> 0.46905164
A14: Operating Expenses:
A15: Research and Development | B15: 29915 | C15: 31370 | D15: 34550 | E15: =(C15-B15)/B15 -> 0.048637807 | F15: =(D15-C15)/C15 -> 0.10137074 | G15: =B15/$B$8 -> 0.078048971 | H15: =C15/$C$8 -> 0.080222998 | I15: =D15/$D$8 -> 0.083020754
A16: Selling, General and Administrative | B16: 24932 | C16: 26097 | D16: 27601 | E16: =(C16-B16)/B16 -> 0.046727098 | F16: =(D16-C16)/C16 -> 0.057631145 | G16: =B16/$B$8 -> 0.065048202 | H16: =C16/$C$8 -> 0.066738272 | I16: =D16/$D$8 -> 0.066322889
A17: Total Operating Expenses | B17: =SUM(B15:B16) -> 54847 | C17: =SUM(C15:C16) -> 57467 | D17: =SUM(D15:D16) -> 62151 | E17: =(C17-B17)/B17 -> 0.047769249 | F17: =(D17-C17)/C17 -> 0.081507648 | G17: =B17/$B$8 -> 0.14309717 | H17: =C17/$C$8 -> 0.14696127 | I17: =D17/$D$8 -> 0.14934364
A18: Operating Income (EBIT) | B18: =B13-B17 -> 114301 | C18: =C13-C17 -> 123216 | D18: =D13-D17 -> 133050 | E18: =(C18-B18)/B18 -> 0.077995818 | F18: =(D18-C18)/C18 -> 0.079811063 | G18: =B18/$B$8 -> 0.29821412 | H18: =C18/$C$8 -> 0.31510223 | I18: =D18/$D$8 -> 0.319708
A19: Other Income/(Expense), net | B19: -565 | C19: 269 | D19: -321 | E19: =(C19-B19)/B19 -> -1.4761062 | F19: =(D19-C19)/C19 -> -2.1933086 | G19: =B19/$B$8 -> -0.0014740989 | H19: =C19/$C$8 -> 0.00068791796 | I19: =D19/$D$8 -> -0.00077133609
A20: Income Before Provision for Income Taxes | B20: =B18+B19 -> 113736 | C20: =C18+C19 -> 123485 | D20: =D18+D19 -> 132729 | E20: =(C20-B20)/B20 -> 0.085716044 | F20: =(D20-C20)/C20 -> 0.074859295 | G20: =B20/$B$8 -> 0.29674002 | H20: =C20/$C$8 -> 0.31579015 | I20: =D20/$D$8 -> 0.31893666
A21: Provision for Income Taxes | B21: 16741 | C21: 29749 | D21: 20719 | E21: =(C21-B21)/B21 -> 0.77701452 | F21: =(D21-C21)/C21 -> -0.30353961 | G21: =B21/$B$8 -> 0.043677681 | H21: =C21/$C$8 -> 0.076077589 | I21: =D21/$D$8 -> 0.04978602
A22: Net Income | B22: =B20-B21 -> 96995 | C22: =C20-C21 -> 93736 | D22: =D20-D21 -> 112010 | E22: =(C22-B22)/B22 -> -0.03359967 | F22: =(D22-C22)/C22 -> 0.19495178 | G22: =B22/$B$8 -> 0.25306234 | H22: =C22/$C$8 -> 0.23971256 | I22: =D22/$D$8 -> 0.26915064
A24: Earnings Per Share — Basic ($) | B24: 6.16 | C24: 6.11 | D24: 7.49 | E24: =(C24-B24)/B24 -> -0.0081168831 | F24: =(D24-C24)/C24 -> 0.22585925 | G24: =B24/$B$8 -> 1.6071592e-05 | H24: =C24/$C$8 -> 1.56252e-05 | I24: =D24/$D$8 -> 1.7997842e-05
A25: Earnings Per Share — Diluted ($) | B25: 6.13 | C25: 6.08 | D25: 7.46 | E25: =(C25-B25)/B25 -> -0.0081566069 | F25: =(D25-C25)/C25 -> 0.22697368 | G25: =B25/$B$8 -> 1.5993321e-05 | H25: =C25/$C$8 -> 1.554848e-05 | I25: =D25/$D$8 -> 1.7925755e-05
A27: Sources: Apple Inc. Form 10-K, FY2023 (period ended Sep 30, 2023), SEC EDGAR: https://www.sec.gov/Archives/edgar/data/320193/000032019323000106/aapl-20230930.htm | Apple Inc. Form 10-K, FY2025 (period ended Sep 27, 2025), SEC EDGAR: https://www.sec.gov/Archives/edgar/data/320193/000032019325000079/aapl-20250927.htm | Apple Inc. Official FY2025 Q4 Consolidated Financial Statements (press release): https://www.apple.com/newsroom/pdfs/fy2025-q4/FY25_Q4_Consolidated_Financial_Statements.pdf

Sheet Balance Sheet
A1: Apple Inc. — Consolidated Balance Sheets
A2: (In millions USD) — As of Fiscal Year-End (last Saturday of September)
A4: Balance Sheet Item | B4: Sep-2023 | C4: Sep-2024 | D4: Sep-2025 | E4: FY24 vs FY23 % | F4: FY25 vs FY24 % | G4: FY23 % Assets | H4: FY24 % Assets | I4: FY25 % Assets
A5: ASSETS
A6: Current Assets:
A7: Cash and Cash Equivalents | B7: 29965 | C7: 29943 | D7: 35934 | E7: =(C7-B7)/B7 -> -0.00073418989 | F7: =(D7-C7)/C7 -> 0.20008015 | G7: =B7/$B$19 -> 0.084987081 | H7: =C7/$C$19 -> 0.082040112 | I7: =D7/$D$19 -> 0.10002756
A8: Marketable Securities (Current) | B8: 31590 | C8: 35228 | D8: 18763 | E8: =(C8-B8)/B8 -> 0.11516303 | F8: =(D8-C8)/C8 -> -0.4673839 | G8: =B8/$B$19 -> 0.089595925 | H8: =C8/$C$19 -> 0.096520357 | I8: =D8/$D$19 -> 0.052229562
A9: Accounts Receivable, net | B9: 29508 | C9: 33410 | D9: 39777 | E9: =(C9-B9)/B9 -> 0.13223533 | F9: =(D9-C9)/C9 -> 0.19057169 | G9: =B9/$B$19 -> 0.083690932 | H9: =C9/$C$19 -> 0.091539262 | I9: =D9/$D$19 -> 0.11072511
A10: Vendor Non-Trade Receivables | B10: 31477 | C10: 32833 | D10: 33180 | E10: =(C10-B10)/B10 -> 0.043079074 | F10: =(D10-C10)/C10 -> 0.010568635 | G10: =B10/$B$19 -> 0.089275433 | H10: =C10/$C$19 -> 0.089958354 | I10: =D10/$D$19 -> 0.092361395
A11: Inventories | B11: 6331 | C11: 7286 | D11: 5718 | E11: =(C11-B11)/B11 -> 0.15084505 | F11: =(D11-C11)/C11 -> -0.21520725 | G11: =B11/$B$19 -> 0.017956056 | H11: =C11/$C$19 -> 0.019962738 | I11: =D11/$D$19 -> 0.015916891
A12: Other Current Assets | B12: 14695 | C12: 14287 | D12: 14585 | E12: =(C12-B12)/B12 -> -0.027764546 | F12: =(D12-C12)/C12 -> 0.020858123 | G12: =B12/$B$19 -> 0.04167813 | H12: =C12/$C$19 -> 0.039144611 | I12: =D12/$D$19 -> 0.040599486
A13: Total Current Assets | B13: =SUM(B7:B12) -> 143566 | C13: =SUM(C7:C12) -> 152987 | D13: =SUM(D7:D12) -> 147957 | E13: =(C13-B13)/B13 -> 0.065621387 | F13: =(D13-C13)/C13 -> -0.032878611 | G13: =B13/$B$19 -> 0.40718356 | H13: =C13/$C$19 -> 0.41916543 | I13: =D13/$D$19 -> 0.41186
A14: Non-Current Assets:
A15: Marketable Securities (Non-Current) | B15: 100544 | C15: 91479 | D15: 77723 | E15: =(C15-B15)/B15 -> -0.090159532 | F15: =(D15-C15)/C15 -> -0.15037331 | G15: =B15/$B$19 -> 0.28516406 | H15: =C15/$C$19 -> 0.25064113 | I15: =D15/$D$19 -> 0.21635337
A16: Property, Plant and Equipment, net | B16: 43715 | C16: 45680 | D16: 49834 | E16: =(C16-B16)/B16 -> 0.044950246 | F16: =(D16-C16)/C16 -> 0.090936953 | G16: =B16/$B$19 -> 0.12398499 | H16: =C16/$C$19 -> 0.12515754 | I16: =D16/$D$19 -> 0.13872025
A17: Other Non-Current Assets | B17: 64758 | C17: 74834 | D17: 83727 | E17: =(C17-B17)/B17 -> 0.15559468 | F17: =(D17-C17)/C17 -> 0.11883636 | G17: =B17/$B$19 -> 0.18366739 | H17: =C17/$C$19 -> 0.20503589 | I17: =D17/$D$19 -> 0.23306638
A18: Total Non-Current Assets | B18: =SUM(B15:B17) -> 209017 | C18: =SUM(C15:C17) -> 211993 | D18: =SUM(D15:D17) -> 211284 | E18: =(C18-B18)/B18 -> 0.014238076 | F18: =(D18-C18)/C18 -> -0.0033444501 | G18: =B18/$B$19 -> 0.59281644 | H18: =C18/$C$19 -> 0.58083457 | I18: =D18/$D$19 -> 0.58814
A19: TOTAL ASSETS | B19: =B13+B18 -> 352583 | C19: =C13+C18 -> 364980 | D19: =D13+D18 -> 359241 | E19: =(C19-B19)/B19 -> 0.035160515 | F19: =(D19-C19)/C19 -> -0.015724149 | G19: =B19/$B$19 -> 1 | H19: =C19/$C$19 -> 1 | I19: =D19/$D$19 -> 1
A21: LIABILITIES AND SHAREHOLDERS' EQUITY
A22: Current Liabilities:
A23: Accounts Payable | B23: 62611 | C23: 68960 | D23: 69860 | E23: =(C23-B23)/B23 -> 0.10140391 | F23: =(D23-C23)/C23 -> 0.013051044 | G23: =B23/$B$19 -> 0.17757805 | H23: =C23/$C$19 -> 0.18894186 | I23: =D23/$D$19 -> 0.19446555
A24: Other Current Liabilities | B24: 58829 | C24: 78304 | D24: 66387 | E24: =(C24-B24)/B24 -> 0.33104421 | F24: =(D24-C24)/C24 -> -0.1521889 | G24: =B24/$B$19 -> 0.16685149 | H24: =C24/$C$19 -> 0.21454326 | I24: =D24/$D$19 -> 0.18479795
A25: Deferred Revenue | B25: 8061 | C25: 8249 | D25: 9055 | E25: =(C25-B25)/B25 -> 0.023322168 | F25: =(D25-C25)/C25 -> 0.097708813 | G25: =B25/$B$19 -> 0.022862702 | H25: =C25/$C$19 -> 0.022601238 | I25: =D25/$D$19 -> 0.02520592
A26: Commercial Paper | B26: 5985 | C26: 9967 | D26: 7979 | E26: =(C26-B26)/B26 -> 0.66532999 | F26: =(D26-C26)/C26 -> -0.19945821 | G26: =B26/$B$19 -> 0.016974727 | H26: =C26/$C$19 -> 0.027308346 | I26: =D26/$D$19 -> 0.022210716
A27: Term Debt (Current) | B27: 9822 | C27: 10912 | D27: 12350 | E27: =(C27-B27)/B27 -> 0.11097536 | F27: =(D27-C27)/C27 -> 0.13178152 | G27: =B27/$B$19 -> 0.02785727 | H27: =C27/$C$19 -> 0.029897529 | I27: =D27/$D$19 -> 0.034378036
A28: Total Current Liabilities | B28: =SUM(B23:B27) -> 145308 | C28: =SUM(C23:C27) -> 176392 | D28: =SUM(D23:D27) -> 165631 | E28: =(C28-B28)/B28 -> 0.21391802 | F28: =(D28-C28)/C28 -> -0.061006168 | G28: =B28/$B$19 -> 0.41212424 | H28: =C28/$C$19 -> 0.48329224 | I28: =D28/$D$19 -> 0.46105818
A29: Non-Current Liabilities:
A30: Term Debt (Non-Current) | B30: 95281 | C30: 85750 | D30: 78328 | E30: =(C30-B30)/B30 -> -0.10003044 | F30: =(D30-C30)/C30 -> -0.086553936 | G30: =B30/$B$19 -> 0.27023708 | H30: =C30/$C$19 -> 0.23494438 | I30: =D30/$D$19 -> 0.21803747
A31: Other Non-Current Liabilities | B31: 49848 | C31: 45888 | D31: 41549 | E31: =(C31-B31)/B31 -> -0.079441502 | F31: =(D31-C31)/C31 -> -0.094556311 | G31: =B31/$B$19 -> 0.14137948 | H31: =C31/$C$19 -> 0.12572744 | I31: =D31/$D$19 -> 0.11565773
A32: Total Non-Current Liabilities | B32: =SUM(B30:B31) -> 145129 | C32: =SUM(C30:C31) -> 131638 | D32: =SUM(D30:D31) -> 119877 | E32: =(C32-B32)/B32 -> -0.092958678 | F32: =(D32-C32)/C32 -> -0.089343503 | G32: =B32/$B$19 -> 0.41161656 | H32: =C32/$C$19 -> 0.36067182 | I32: =D32/$D$19 -> 0.33369521
A33: TOTAL LIABILITIES | B33: =B28+B32 -> 290437 | C33: =C28+C32 -> 308030 | D33: =D28+D32 -> 285508 | E33: =(C33-B33)/B33 -> 0.060574238 | F33: =(D33-C33)/C33 -> -0.073116255 | G33: =B33/$B$19 -> 0.82374079 | H33: =C33/$C$19 -> 0.84396405 | I33: =D33/$D$19 -> 0.79475338
A35: Shareholders' Equity:
A36: Common Stock and Additional Paid-in Capital | B36: 73812 | C36: 83276 | D36: 93568 | E36: =(C36-B36)/B36 -> 0.12821763 | F36: =(D36-C36)/C36 -> 0.12358903 | G36: =B36/$B$19 -> 0.20934645 | H36: =C36/$C$19 -> 0.22816593 | I36: =D36/$D$19 -> 0.26046025
A37: Retained Earnings / (Accumulated Deficit) | B37: -214 | C37: -19154 | D37: -14264 | E37: =(C37-B37)/B37 -> 88.504673 | F37: =(D37-C37)/C37 -> -0.25529915 | G37: =B37/$B$19 -> -0.00060694929 | H37: =C37/$C$19 -> -0.052479588 | I37: =D37/$D$19 -> -0.039705936
A38: Accumulated Other Comprehensive Loss | B38: -11452 | C38: -7172 | D38: -5571 | E38: =(C38-B38)/B38 -> -0.37373385 | F38: =(D38-C38)/C38 -> -0.22322922 | G38: =B38/$B$19 -> -0.032480295 | H38: =C38/$C$19 -> -0.019650392 | I38: =D38/$D$19 -> -0.015507695
A39: TOTAL SHAREHOLDERS' EQUITY | B39: =SUM(B36:B38) -> 62146 | C39: =SUM(C36:C38) -> 56950 | D39: =SUM(D36:D38) -> 73733 | E39: =(C39-B39)/B39 -> -0.083609565 | F39: =(D39-C39)/C39 -> 0.2946971 | G39: =B39/$B$19 -> 0.17625921 | H39: =C39/$C$19 -> 0.15603595 | I39: =D39/$D$19 -> 0.20524662
A40: TOTAL LIABILITIES AND SHAREHOLDERS' EQUITY | B40: =B33+B39 -> 352583 | C40: =C33+C39 -> 364980 | D40: =D33+D39 -> 359241 | E40: =(C40-B40)/B40 -> 0.035160515 | F40: =(D40-C40)/C40 -> -0.015724149 | G40: =B40/$B$19 -> 1 | H40: =C40/$C$19 -> 1 | I40: =D40/$D$19 -> 1
A41: Balance Check (should be 0) | B41: =B19-B40 -> 0 | C41: =C19-C40 -> 0 | D41: =D19-D40 -> 0
A44: Reference: Prior-Year Closing Balances (for Average Ratio Calculations)
A45: Total Assets (Sep-2022) | B45: 352755
...

Sheet Cash Flow Statement
A1: Apple Inc. — Consolidated Statements of Cash Flows
A2: (In millions USD) — Fiscal Years Ended Sept
A4: Cash Flow Item | B4: FY2023 | C4: FY2024 | D4: FY2025 | E4: FY24 vs FY23 % | F4: FY25 vs FY24 %
A5: Cash, Cash Equivalents and Restricted Cash — Beginning | B5: 24977 | C5: =B39 -> 30737 | D5: =C39 -> 29943
A7: Operating Activities:
A8: Net Income | B8: 96995 | C8: 93736 | D8: 112010 | E8: =(C8-B8)/B8 -> -0.03359967 | F8: =(D8-C8)/C8 -> 0.19495178
A9: Depreciation and Amortization | B9: 11519 | C9: 11445 | D9: 11698 | E9: =(C9-B9)/B9 -> -0.0064241688 | F9: =(D9-C9)/C9 -> 0.022105723
A10: Share-Based Compensation Expense | B10: 10833 | C10: 11688 | D10: 12863 | E10: =(C10-B10)/B10 -> 0.078925505 | F10: =(D10-C10)/C10 -> 0.10053046
A11: Other | B11: -2227 | C11: -2266 | D11: -89 | E11: =(C11-B11)/B11 -> 0.017512348 | F11: =(D11-C11)/C11 -> -0.96072374
A12: Change in Accounts Receivable, net | C12: -3788 | D12: -6682 | E12: =(C12-B12)/B12 -> #DIV/0! | F12: =(D12-C12)/C12 -> 0.76399155
A13: Change in Vendor Non-Trade Receivables | C13: -1356 | D13: -347 | E13: =(C13-B13)/B13 -> #DIV/0! | F13: =(D13-C13)/C13 -> -0.74410029
A14: Change in Inventories | C14: -1046 | D14: 1400 | E14: =(C14-B14)/B14 -> #DIV/0! | F14: =(D14-C14)/C14 -> -2.3384321
A15: Change in Other Current and Non-Current Assets | C15: -11731 | D15: -9197 | E15: =(C15-B15)/B15 -> #DIV/0! | F15: =(D15-C15)/C15 -> -0.21600887
A16: Change in Accounts Payable | C16: 6020 | D16: 902 | E16: =(C16-B16)/B16 -> #DIV/0! | F16: =(D16-C16)/C16 -> -0.85016611
A17: Change in Other Current and Non-Current Liabilities | C17: 15552 | D17: -11076 | E17: =(C17-B17)/B17 -> #DIV/0! | F17: =(D17-C17)/C17 -> -1.7121914
A18: Cash Generated by Operating Activities | B18: 110543 | C18: =SUM(C8:C17) -> 118254 | D18: =SUM(D8:D17) -> 111482 | E18: =(C18-B18)/B18 -> 0.069755661 | F18: =(D18-C18)/C18 -> -0.057266562
A20: Investing Activities:
A21: Purchases of Marketable Securities | B21: -29513 | C21: -48656 | D21: -24407 | E21: =(C21-B21)/B21 -> 0.64862942 | F21: =(D21-C21)/C21 -> -0.49837636
A22: Proceeds from Maturities of Marketable Securities | B22: 39686 | C22: 51211 | D22: 40907 | E22: =(C22-B22)/B22 -> 0.29040468 | F22: =(D22-C22)/C22 -> -0.20120677
A23: Proceeds from Sales of Marketable Securities | B23: 5828 | C23: 11135 | D23: 12890 | E23: =(C23-B23)/B23 -> 0.91060398 | F23: =(D23-C23)/C23 -> 0.15761114
A24: Payments for Acquisition of PP&E | B24: -10959 | C24: -9447 | D24: -12715 | E24: =(C24-B24)/B24 -> -0.13796879 | F24: =(D24-C24)/C24 -> 0.34592992
A25: Other | B25: -1337 | C25: -1308 | D25: -1480 | E25: =(C25-B25)/B25 -> -0.021690352 | F25: =(D25-C25)/C25 -> 0.13149847
A26: Cash Generated by Investing Activities | B26: =SUM(B21:B25) -> 3705 | C26: =SUM(C21:C25) -> 2935 | D26: =SUM(D21:D25) -> 15195 | E26: =(C26-B26)/B26 -> -0.20782726 | F26: =(D26-C26)/C26 -> 4.1771721
A28: Financing Activities:
A29: Payments for Taxes Related to Net Share Settlement of Equity Awards | B29: -5431 | C29: -5441 | D29: -5960 | E29: =(C29-B29)/B29 -> 0.0018412815 | F29: =(D29-C29)/C29 -> 0.095386877
A30: Payments for Dividends and Dividend Equivalents | B30: -15025 | C30: -15234 | D30: -15421 | E30: =(C30-B30)/B30 -> 0.01391015 | F30: =(D30-C30)/C30 -> 0.012275174
A31: Repurchases of Common Stock | B31: -77550 | C31: -94949 | D31: -90711 | E31: =(C31-B31)/B31 -> 0.22435848 | F31: =(D31-C31)/C31 -> -0.044634488
A32: Proceeds from Issuance of Term Debt, net | B32: 5228 | C32: 0 | D32: 4481 | E32: =(C32-B32)/B32 -> -1 | F32: =(D32-C32)/C32 -> #DIV/0!
A33: Repayments of Term Debt | B33: -11151 | C33: -9958 | D33: -10932 | E33: =(C33-B33)/B33 -> -0.10698592 | F33: =(D33-C33)/C33 -> 0.097810805
A34: Proceeds from/(Repayments of) Commercial Paper, net | B34: -3978 | C34: 3960 | D34: -2032 | E34: =(C34-B34)/B34 -> -1.9954751 | F34: =(D34-C34)/C34 -> -1.5131313
A35: Other | B35: -581 | C35: -361 | D35: -111 | E35: =(C35-B35)/B35 -> -0.37865749 | F35: =(D35-C35)/C35 -> -0.69252078
A36: Cash Used in Financing Activities | B36: =SUM(B29:B35) -> -108488 | C36: =SUM(C29:C35) -> -121983 | D36: =SUM(D29:D35) -> -120686 | E36: =(C36-B36)/B36 -> 0.12439164 | F36: =(D36-C36)/C36 -> -0.010632629
A38: Increase/(Decrease) in Cash, Cash Equivalents and Restricted Cash | B38: =B18+B26+B36 -> 5760 | C38: =C18+C26+C36 -> -794 | D38: =D18+D26+D36 -> 5991 | E38: =(C38-B38)/B38 -> -1.1378472 | F38: =(D38-C38)/C38 -> -8.5453401
A39: Cash, Cash Equivalents and Restricted Cash — Ending | B39: =B5+B38 -> 30737 | C39: =C5+C38 -> 29943 | D39: =D5+D38 -> 35934 | E39: =(C39-B39)/B39 -> -0.025832059 | F39: =(D39-C39)/C39 -> 0.20008015
A41: Supplemental Disclosure:
A42: Cash Paid for Income Taxes, net | B42: 18679 | C42: 26102 | D42: 43369 | E42: =(C42-B42)/B42 -> 0.39739815 | F42: =(D42-C42)/C42 -> 0.66152019
A43: Cash Paid for Interest | B43: 3803 | E43: =(C43-B43)/B43 -> -1 | F43: =(D43-C43)/C43 -> #DIV/0!
A45: Sources: Apple Inc. Form 10-K, FY2023 (period ended Sep 30, 2023), SEC EDGAR: https://www.sec.gov/Archives/edgar/data/320193/000032019323000106/aapl-20230930.htm | Apple Inc. Form 10-K, FY2025 (period ended Sep 27, 2025), SEC EDGAR: https://www.sec.gov/Archives/edgar/data/320193/000032019325000079/aapl-20250927.htm | Apple Inc. Official FY2025 Q4 Consolidated Financial Statements (press release): https://www.apple.com/newsroom/pdfs/fy2025-q4/FY25_Q4_Consolidated_Financial_Statements.pdf

Sheet Ratio Analysis
A1: Ratio | B1: FY2023 | C1: FY2024 | D1: FY2025
A2: Liquidity Ratios
A3: Current Ratio | B3: ='Balance Sheet'!B13/'Balance Sheet'!B28 -> 0.98801167 | C3: ='Balance Sheet'!C13/'Balance Sheet'!C28 -> 0.86731258 | D3: ='Balance Sheet'!D13/'Balance Sheet'!D28 -> 0.89329292
A4: Quick Ratio | B4: =('Balance Sheet'!B13-'Balance Sheet'!B11)/'Balance Sheet'!B28 -> 0.94444215 | C4: =('Balance Sheet'!C13-'Balance Sheet'!C11)/'Balance Sheet'!C28 -> 0.82600685 | D4: =('Balance Sheet'!D13-'Balance Sheet'!D11)/'Balance Sheet'!D28 -> 0.8587704
A5: Cash Ratio | B5: ='Balance Sheet'!B7/'Balance Sheet'!B28 -> 0.20621714 | C5: ='Balance Sheet'!C7/'Balance Sheet'!C28 -> 0.1697526 | D5: ='Balance Sheet'!D7/'Balance Sheet'!D28 -> 0.21695214
A6: Profitability Ratios
A7: Gross Margin % | B7: ='Income Statement'!B13/'Income Statement'!B8 -> 0.4413113 | C7: ='Income Statement'!C13/'Income Statement'!C8 -> 0.4620635 | D7: ='Income Statement'!D13/'Income Statement'!D8 -> 0.46905164
A8: Operating Margin % | B8: ='Income Statement'!B18/'Income Statement'!B8 -> 0.29821412 | C8: ='Income Statement'!C18/'Income Statement'!C8 -> 0.31510223 | D8: ='Income Statement'!D18/'Income Statement'!D8 -> 0.319708
A9: Net Profit Margin % | B9: ='Income Statement'!B22/'Income Statement'!B8 -> 0.25306234 | C9: ='Income Statement'!C22/'Income Statement'!C8 -> 0.23971256 | D9: ='Income Statement'!D22/'Income Statement'!D8 -> 0.26915064
A10: Return on Assets (ROA) | B10: ='Income Statement'!B22/(('Balance Sheet'!B45+'Balance Sheet'!B19)/2) -> 0.27503126 | C10: ='Income Statement'!C22/(('Balance Sheet'!B19+'Balance Sheet'!C19)/2) -> 0.26126208 | D10: ='Income Statement'!D22/(('Balance Sheet'!C19+'Balance Sheet'!D19)/2) -> 0.30932547
A11: Return on Equity (ROE) | B11: ='Income Statement'!B22/(('Balance Sheet'!B46+'Balance Sheet'!B39)/2) -> 1.7194951 | C11: ='Income Statement'!C22/(('Balance Sheet'!B39+'Balance Sheet'!C39)/2) -> 1.5741251 | D11: ='Income Statement'!D22/(('Balance Sheet'!C39+'Balance Sheet'!D39)/2) -> 1.7142245
A12: Leverage/Solvency Ratios
A13: Debt-to-Equity Ratio | B13: ='Balance Sheet'!B33/'Balance Sheet'!B39 -> 4.6734625 | C13: ='Balance Sheet'!C33/'Balance Sheet'!C39 -> 5.4087796 | D13: ='Balance Sheet'!D33/'Balance Sheet'!D39 -> 3.8721875
A14: Interest Coverage Ratio (FY2023 only) | B14: =('Income Statement'!B18)/3933 -> 29.062039
A15: Efficiency Ratios
A16: Inventory Turnover | C16: ='Income Statement'!C10/(('Balance Sheet'!B11+'Balance Sheet'!C11)/2) -> 27.206139 | D16: ='Income Statement'!D10/(('Balance Sheet'!C11+'Balance Sheet'!D11)/2) -> 29.854814
A17: Receivables Turnover | C17: ='Income Statement'!C8/(('Balance Sheet'!B9+'Balance Sheet'!C9)/2) -> 12.429988 | D17: ='Income Statement'!D8/(('Balance Sheet'!C9+'Balance Sheet'!D9)/2) -> 11.372539
A18: Days Sales Outstanding (DSO) | C18: =365/C17 -> 29.364469 | D18: =365/D17 -> 32.094856
A19: Payables Turnover | C19: ='Income Statement'!C12/(('Balance Sheet'!B23+'Balance Sheet'!C23)/2) -> 3.1975435 | D19: ='Income Statement'!D12/(('Balance Sheet'!C23+'Balance Sheet'!D23)/2) -> 3.183403
A20: Days Payable Outstanding (DPO) | C20: =365/C19 -> 114.15013 | D20: =365/D19 -> 114.65718

Sheet Comps Analysis
A1: Company | B1: Trailing P/E | C1: EV/EBITDA
A2: Peer Group
A3: Apple (AAPL) | B3: 36.71 | C3: 27.43
A4: Microsoft (MSFT) | B4: 27.39 | C4: 19.07
A5: Alphabet (GOOGL) | B5: 17.39 | C5: 23.78
A6: Peer Average (excl. Apple) | B6: =AVERAGE(B4:B5) -> 22.39 | C6: =AVERAGE(C4:C5) -> 21.425
A7: Implied Valuation
A8: Apple Actual Stock Price | B8: 319.97
A9: Apple EPS (TTM) | B9: 8.72
A10: Apple EBITDA (TTM, $M) | B10: 169006
A11: Implied Price per Share (P/E Method) | B11: =B6*B9 -> 195.2408
A12: Implied Enterprise Value, $M (EV/EBITDA Method) | B12: =C6*B10 -> 3620953.5

Sheet DCF Valuation
A1: Unlevered FCF Build-up
B2: FY2023 | C2: FY2024 | D2: FY2025
A3: EBIT (Operating Income) | B3: ='Income Statement'!B18 -> 114301 | C3: ='Income Statement'!C18 -> 123216 | D3: ='Income Statement'!D18 -> 133050
A4: Effective Tax Rate | B4: ='Income Statement'!B21/'Income Statement'!B20 -> 0.14719174 | C4: ='Income Statement'!C21/'Income Statement'!C20 -> 0.24091185 | D4: ='Income Statement'!D21/'Income Statement'!D20 -> 0.15610002
A5: NOPAT | B5: =B3*(1-B4) -> 97476.837 | C5: =C3*(1-C4) -> 93531.805 | D5: =D3*(1-D4) -> 112280.89
A6: (+) Depreciation & Amortization | B6: ='Cash Flow Statement'!B9 -> 11519 | C6: ='Cash Flow Statement'!C9 -> 11445 | D6: ='Cash Flow Statement'!D9 -> 11698
A7: (-) Capital Expenditures | B7: =-'Cash Flow Statement'!B24 -> 10959 | C7: =-'Cash Flow Statement'!C24 -> 9447 | D7: =-'Cash Flow Statement'!D24 -> 12715
A9: Operating Current Assets (excl. Cash) | B9: ='Balance Sheet'!B4+'Balance Sheet'!B5+'Balance Sheet'!B6+'Balance Sheet'!B7 -> 75135 | C9: ='Balance Sheet'!C4+'Balance Sheet'!C5+'Balance Sheet'!C6+'Balance Sheet'!C7 -> 75479 | D9: ='Balance Sheet'!D4+'Balance Sheet'!D5+'Balance Sheet'!D6+'Balance Sheet'!D7 -> 81835
A10: Operating Current Liabilities (excl. short-term debt) | B10: ='Balance Sheet'!B14+'Balance Sheet'!B15+'Balance Sheet'!B16 -> 144259 | C10: ='Balance Sheet'!C14+'Balance Sheet'!C15+'Balance Sheet'!C16 -> 137159 | D10: ='Balance Sheet'!D14+'Balance Sheet'!D15+'Balance Sheet'!D16 -> 127557
A11: Net Working Capital | B11: =B9-B10 -> -69124 | C11: =C9-C10 -> -61680 | D11: =D9-D10 -> -45722
A12: Change in NWC | C12: =C11-B11 -> 7444 | D12: =D11-C11 -> 15958
A13: (+) Decrease / (-) Increase in NWC → FCF Impact | C13: =-C12 -> -7444 | D13: =-D12 -> -15958
A14: Unlevered Free Cash Flow (UFCF) | C14: =C5+C6-C7+C13 -> 88085.805 | D14: =D5+D6-D7+D13 -> 95305.892
A16: FCF Margin (FY2025, base year) | D16: =D14/'Income Statement'!D8 -> 0.22901207
A19: Projection Years | B19: FY2026 | C19: FY2027 | D19: FY2028 | E19: FY2029 | F19: FY2030
A20: Revenue Growth Rate (Assumption) | B20: 0.065 | C20: 0.065 | D20: 0.065 | E20: 0.065 | F20: 0.065
A21: Projected Revenue | B21: ='Income Statement'!D8*(1+B20) -> 443211.47 | C21: =B21*(1+C20) -> 472020.21 | D21: =C21*(1+D20) -> 502701.52 | E21: =D21*(1+E20) -> 535377.12 | F21: =E21*(1+F20) -> 570176.64
A22: Projected Unlevered FCF | B22: =B21*$D$16 -> 101500.77 | C22: =C21*$D$16 -> 108098.33 | D22: =D21*$D$16 -> 115124.72 | E22: =E21*$D$16 -> 122607.82 | F22: =F21*$D$16 -> 130577.33
A23: Discount Period (n) | B23: 1 | C23: 2 | D23: 3 | E23: 4 | F23: 5
A24: Present Value of UFCF | B24: =B22/(1+$B$38)^B23 -> 92621.136 | C24: =C22/(1+$B$38)^C23 -> 90012.01 | D24: =D22/(1+$B$38)^D23 -> 87476.383 | E24: =E22/(1+$B$38)^E23 -> 85012.184 | F24: =F22/(1+$B$38)^F23 -> 82617.401
A25: Risk-Free Rate | B25: 0.0484
A26: Beta | B26: 1.09
A27: Equity Risk Premium | B27: 0.0445
A28: Cost of Equity (CAPM) | B28: =B25+(B26*B27) -> 0.096905
A30: Market Value of Equity E | B30: =319.97*14590 -> 4668362.3
A31: Total Debt (D) | B31: ='Balance Sheet'!D26+'Balance Sheet'!D27+'Balance Sheet'!D30 -> 98657
A32: Total Capital (V = E + D) | B32: =B30+B31 -> 4767019.3
A33: Weight of Equity (E/V) | B33: =B30/B32 -> 0.97930426
A34: Weight of Debt (D/V) | B34: =B31/B32 -> 0.020695742
A35: Cost of Debt (Pre-Tax) | B35: 0.0556
A36: After-Tax Cost of Debt | B36: =B35*(1-'Income Statement'!D21/'Income Statement'!D20) -> 0.046920839
A38: WACC | B38: =(B33*B28)+(B34*B36) -> 0.095870541
A40: Perpetuity Growth Rate (g) | B40: 0.025
A41: Terminal Value (at end of FY2030) | B41: =(F22*(1+B40))/(B38-B40) -> 1888538.8
A42: Present Value of Terminal Value | B42: =B41/(1+$B$38)^F23 -> 1194894.7
A44: Sum of PV of Projected UFCF (FY2026-2030) | B44: =SUM(B24:F24) -> 437739.11
A45: Enterprise Value (EV) | B45: =B44+B42 -> 1632633.8
A46: (-) Total Debt | B46: ='Balance Sheet'!D26+'Balance Sheet'!D27+'Balance Sheet'!D30 -> 98657
A47: (+) Cash and Cash Equivalents | B47: ='Balance Sheet'!D7 -> 35934
A48: Equity Value | B48: =B45-B46+B47 -> 1569910.8
...

Sheet Altman Z-Score
A1: Working Capital / Total Assets
A2: Working Capital | B2: ='Balance Sheet'!D13-'Balance Sheet'!D28 -> -17674
A3: Total Assets | B3: ='Balance Sheet'!D19 -> 359241
A4: A = Working Capital / Total Assets | B4: =B2/B3 -> -0.049198171
A5: Retained Earnings / Total Assets | B5: ='Balance Sheet'!D37 -> -14264
A6: Retained Earnings / Total Assets
A7: Retained Earnings/(Accumulated Deficit) | B7: ='Balance Sheet'!D37 -> -14264
A8: B = Retained Earnings / Total Assets | B8: =B7/B3 -> -0.039705936
A9: EBIT / Total Assets
A10: EBIT | B10: ='Income Statement'!D18 -> 133050
A11: C = EBIT / Total Assets | B11: =B10/B3 -> 0.37036418
A12: Market Value of Equity / Total Liabilities
A13: Market Value of Equity | B13: ='DCF Valuation'!B30 -> 4668362.3
A14: Total Liabilities | B14: ='Balance Sheet'!D33 -> 285508
A15: D = Market Value of Equity / Total Liabilities | B15: =B13/B14 -> 16.351074
A16: Sales / Total Assets
A17: Total Net Sales | B17: ='Income Statement'!D8 -> 416161
A18: E = Sales / Total Assets | B18: =B17/B3 -> 1.1584452
A19: Altman Z-Score | B19: =(1.2*B4)+(1.4*B8)+(3.3*B11)+(0.6*B15)+(1*B18) -> 12.076665
